mplus_output/uni-11-HRS_W11.out
Mplus VERSION 8.1 (Mac)
MUTHEN & MUTHEN
05/27/2020  10:28 PM

INPUT INSTRUCTIONS

  DATA:
  FILE = "uni-11-HRS_W11.dat";

  VARIABLE:
  NAMES = mplusid UDAT UDAY UMON UYER UIWR UDWR USUB UBAK UNM1 UNM2 UNM5 UNM6 URE3
       URE5 URE6;
   MISSING=.;
   CATEGORICAL ARE all; idvariable = mplusid;
  ANALYSIS:
  estimator = wlsmv; coverage=0;
  MODEL:
  g by UDAT * ;
   g by UDAY * ;
   g by UMON * ;
   g by UYER * ;
   g by UIWR * ;
   g by UDWR * ;
   g by USUB * ;
   g by UBAK * ;
   g by UNM1 * ;
   g by UNM2 * ;
   g by UNM5 * ;
   g by UNM6 * ;
   g by URE3 * ;
   g by URE5 * ;
   g by URE6 * ;
   g @ 1;

  OUTPUT:
  standardized; svalues;



*** WARNING
  Data set contains cases with missing on all variables.
  These cases were not included in the analysis.
  Number of cases with missing on all variables:  1166
   1 WARNING(S) FOUND IN THE INPUT INSTRUCTIONS




SUMMARY OF ANALYSIS

Number of groups                                                 1
Number of observations                                       16051

Number of dependent variables                                   15
Number of independent variables                                  0
Number of continuous latent variables                            1

Observed dependent variables

  Binary and ordered categorical (ordinal)
   UDAT        UDAY        UMON        UYER        UIWR        UDWR
   USUB        UBAK        UNM1        UNM2        UNM5        UNM6
   URE3        URE5        URE6

Continuous latent variables
   G

Variables with special functions

  ID variable           MPLUSID

Estimator                                                    WLSMV
Maximum number of iterations                                  1000
Convergence criterion                                    0.500D-04
Maximum number of steepest descent iterations                   20
Maximum number of iterations for H1                           2000
Convergence criterion for H1                             0.100D-03
Parameterization                                             DELTA
Link                                                        PROBIT

Input data file(s)
  uni-11-HRS_W11.dat

Input data format  FREE


SUMMARY OF DATA

     Number of missing data patterns           177


COVARIANCE COVERAGE OF DATA

Minimum covariance coverage value   0.000


     PROPORTION OF DATA PRESENT


           Covariance Coverage
              UDAT          UDAY          UMON          UYER          UIWR
              ________      ________      ________      ________      ________
 UDAT           0.640
 UDAY           0.638         0.649
 UMON           0.639         0.646         0.648
 UYER           0.638         0.646         0.646         0.647
 UIWR           0.635         0.644         0.643         0.642         0.994
 UDWR           0.635         0.644         0.643         0.642         0.994
 USUB           0.591         0.598         0.597         0.597         0.927
 UBAK           0.634         0.643         0.642         0.642         0.644
 UNM1           0.638         0.647         0.647         0.646         0.647
 UNM2           0.610         0.618         0.618         0.617         0.616
 UNM5           0.631         0.639         0.638         0.638         0.637
 UNM6           0.549         0.553         0.553         0.553         0.551
 URE3           0.008         0.008         0.008         0.008         0.008
 URE5           0.006         0.006         0.006         0.006         0.006
 URE6           0.006         0.006         0.006         0.006         0.006


           Covariance Coverage
              UDWR          USUB          UBAK          UNM1          UNM2
              ________      ________      ________      ________      ________
 UDWR           0.994
 USUB           0.927         0.930
 UBAK           0.644         0.598         0.648
 UNM1           0.647         0.599         0.646         0.652
 UNM2           0.616         0.578         0.616         0.620         0.621
 UNM5           0.637         0.593         0.636         0.641         0.613
 UNM6           0.551         0.522         0.550         0.554         0.539
 URE3           0.008         0.008         0.008         0.008         0.007
 URE5           0.006         0.006         0.006         0.006         0.006
 URE6           0.006         0.006         0.006         0.006         0.006


           Covariance Coverage
              UNM5          UNM6          URE3          URE5          URE6
              ________      ________      ________      ________      ________
 UNM5           0.642
 UNM6           0.553         0.555
 URE3           0.008         0.006         0.008
 URE5           0.006         0.005         0.006         0.006
 URE6           0.006         0.005         0.006         0.006         0.006


UNIVARIATE PROPORTIONS AND COUNTS FOR CATEGORICAL VARIABLES

    UDAT
      Category 1    0.174         1783.000
      Category 2    0.826         8482.000
    UDAY
      Category 1    0.036          379.000
      Category 2    0.964        10037.000
    UMON
      Category 1    0.033          345.000
      Category 2    0.967        10056.000
    UYER
      Category 1    0.033          338.000
      Category 2    0.967        10054.000
    UIWR
      Category 1    0.008          122.000
      Category 2    0.010          154.000
      Category 3    0.031          492.000
      Category 4    0.082         1307.000
      Category 5    0.167         2667.000
      Category 6    0.452         7201.000
      Category 7    0.154         2454.000
      Category 8    0.070         1112.000
      Category 9    0.022          349.000
      Category 10    0.006           89.000
    UDWR
      Category 1    0.063         1010.000
      Category 2    0.040          630.000
      Category 3    0.074         1177.000
      Category 4    0.136         2172.000
      Category 5    0.201         3199.000
      Category 6    0.353         5634.000
      Category 7    0.083         1331.000
      Category 8    0.034          539.000
      Category 9    0.012          192.000
      Category 10    0.004           63.000
    USUB
      Category 1    0.037          555.000
      Category 2    0.106         1578.000
      Category 3    0.082         1224.000
      Category 4    0.130         1948.000
      Category 5    0.197         2947.000
      Category 6    0.447         6681.000
    UBAK
      Category 1    0.061          635.000
      Category 2    0.939         9764.000
    UNM1
      Category 1    0.011          110.000
      Category 2    0.989        10360.000
    UNM2
      Category 1    0.047          469.000
      Category 2    0.953         9499.000
    UNM5
      Category 1    0.018          185.000
      Category 2    0.982        10122.000
    UNM6
      Category 1    0.120         1072.000
      Category 2    0.880         7835.000
    URE3
      Category 1    0.210           26.000
      Category 2    0.790           98.000
    URE5
      Category 1    0.530           53.000
      Category 2    0.470           47.000
    URE6
      Category 1    0.534           55.000
      Category 2    0.388           40.000
      Category 3    0.078            8.000


     WARNING:  THE BIVARIATE TABLE OF URE3 AND UMON HAS AN EMPTY CELL.

     WARNING:  THE BIVARIATE TABLE OF URE3 AND UYER HAS AN EMPTY CELL.

     WARNING:  THE BIVARIATE TABLE OF URE3 AND UNM5 HAS AN EMPTY CELL.

     WARNING:  THE BIVARIATE TABLE OF URE5 AND UDAY HAS AN EMPTY CELL.

     WARNING:  THE BIVARIATE TABLE OF URE5 AND UMON HAS AN EMPTY CELL.

     WARNING:  THE BIVARIATE TABLE OF URE5 AND UYER HAS AN EMPTY CELL.

     WARNING:  THE BIVARIATE TABLE OF URE5 AND UNM5 HAS AN EMPTY CELL.

     WARNING:  THE BIVARIATE TABLE OF URE5 AND UNM5 HAS AN EMPTY CELL.

     WARNING:  THE SAMPLE CORRELATION OF URE6 AND UDAY IS  0.986
     DUE TO ONE OR MORE ZERO CELLS IN THEIR BIVARIATE TABLE.
     INFORMATION FROM THESE VARIABLES CAN BE USED TO CREATE ONE NEW VARIABLE.
